<?xml version="1.0" encoding="UTF-8"?>
<robot name="ve026a">
	<gazebo>
		<plugin name="gazebo_ros_control" filename="libgazebo_ros_control.so">
			<robotNamespace>/ve026a</robotNamespace>
		</plugin>
	</gazebo>
	<link name="world"/>
	<joint name="joint_w" type="fixed">
		<parent link="world"/>
		<child link="base_link"/>
	</joint>
	<link name="base_link">
		<visual>
			<origin rpy="0 0 0" xyz="0 0 0"/>
			<geometry>
				<mesh filename="package://denso_robot_descriptions/ve026a_description/base_link.dae" scale="1 1 1"/>
			</geometry>
		</visual>
		<collision>
			<origin rpy="0 0 0" xyz="0 0 0"/>
			<geometry>
				<mesh filename="package://denso_robot_descriptions/ve026a_description/base_link.dae" scale="1 1 1"/>
			</geometry>
		</collision>
		<inertial>
			<mass value="1"/>
			<origin rpy="0.000000 0.000000 0.000000" xyz="0.000000 0.000000 0.000000"/>
			<inertia ixx="1" ixy="0" ixz="0" iyy="1" iyz="0" izz="1"/>
		</inertial>
	</link>
	<link name="J1">
		<visual>
			<origin rpy="0 0 0" xyz="0 0 0"/>
			<geometry>
				<mesh filename="package://denso_robot_descriptions/ve026a_description/J1.dae" scale="1 1 1"/>
			</geometry>
		</visual>
		<collision>
			<origin rpy="0 0 0" xyz="0 0 0"/>
			<geometry>
				<mesh filename="package://denso_robot_descriptions/ve026a_description/J1.dae" scale="1 1 1"/>
			</geometry>
		</collision>
		<inertial>
			<mass value="1"/>
			<origin rpy="0.000000 0.000000 0.000000" xyz="0.000000 0.000000 0.000000"/>
			<inertia ixx="1" ixy="0" ixz="0" iyy="1" iyz="0" izz="1"/>
		</inertial>
	</link>
	<joint name="joint_1" type="revolute">
		<parent link="base_link"/>
		<child link="J1"/>
		<origin rpy="0.000000 0.000000 0.000000" xyz="0.000000 0.000000 0.000000"/>
		<axis xyz="-0.000000 -0.000000 1.000000"/>
		<limit effort="1" lower="-1.396263" upper="1.832596" velocity="1"/>
		<dynamics damping="0" friction="0"/>
	</joint>
	<transmission name="trans_1">
		<type>transmission_interface/SimpleTransmission</type>
		<joint name="joint_1">
			<hardwareInterface>PositionJointInterface</hardwareInterface>
		</joint>
		<actuator name="motor_1">
			<hardwareInterface>PositionJointInterface</hardwareInterface>
			<mechanicalReduction>1</mechanicalReduction>
		</actuator>
	</transmission>
	<link name="J2">
		<visual>
			<origin rpy="0 0 0" xyz="0 0 0"/>
			<geometry>
				<mesh filename="package://denso_robot_descriptions/ve026a_description/J2.dae" scale="1 1 1"/>
			</geometry>
		</visual>
		<collision>
			<origin rpy="0 0 0" xyz="0 0 0"/>
			<geometry>
				<mesh filename="package://denso_robot_descriptions/ve026a_description/J2.dae" scale="1 1 1"/>
			</geometry>
		</collision>
		<inertial>
			<mass value="1"/>
			<origin rpy="0.000000 0.000000 0.000000" xyz="0.000000 0.000000 0.000000"/>
			<inertia ixx="1" ixy="0" ixz="0" iyy="1" iyz="0" izz="1"/>
		</inertial>
	</link>
	<joint name="joint_2" type="revolute">
		<parent link="J1"/>
		<child link="J2"/>
		<origin rpy="0.000000 0.000000 0.000000" xyz="0.000000 0.000000 0.130000"/>
		<axis xyz="-0.000000 1.000000 -0.000000"/>
		<limit effort="1" lower="-0.6108652" upper="1.570796" velocity="1"/>
		<dynamics damping="0" friction="0"/>
	</joint>
	<transmission name="trans_2">
		<type>transmission_interface/SimpleTransmission</type>
		<joint name="joint_2">
			<hardwareInterface>PositionJointInterface</hardwareInterface>
		</joint>
		<actuator name="motor_2">
			<hardwareInterface>PositionJointInterface</hardwareInterface>
			<mechanicalReduction>1</mechanicalReduction>
		</actuator>
	</transmission>
	<link name="J3">
		<visual>
			<origin rpy="0 0 0" xyz="0 0 0"/>
			<geometry>
				<mesh filename="package://denso_robot_descriptions/ve026a_description/J3.dae" scale="1 1 1"/>
			</geometry>
		</visual>
		<collision>
			<origin rpy="0 0 0" xyz="0 0 0"/>
			<geometry>
				<mesh filename="package://denso_robot_descriptions/ve026a_description/J3.dae" scale="1 1 1"/>
			</geometry>
		</collision>
		<inertial>
			<mass value="1"/>
			<origin rpy="0.000000 0.000000 0.000000" xyz="0.000000 0.000000 0.000000"/>
			<inertia ixx="1" ixy="0" ixz="0" iyy="1" iyz="0" izz="1"/>
		</inertial>
	</link>
	<joint name="joint_3" type="revolute">
		<parent link="J2"/>
		<child link="J3"/>
		<origin rpy="0.000000 0.000000 0.000000" xyz="0.000000 0.000000 0.100000"/>
		<axis xyz="-0.000000 1.000000 -0.000000"/>
		<limit effort="1" lower="-1.308997" upper="2.356194" velocity="1"/>
		<dynamics damping="0" friction="0"/>
	</joint>
	<transmission name="trans_3">
		<type>transmission_interface/SimpleTransmission</type>
		<joint name="joint_3">
			<hardwareInterface>PositionJointInterface</hardwareInterface>
		</joint>
		<actuator name="motor_3">
			<hardwareInterface>PositionJointInterface</hardwareInterface>
			<mechanicalReduction>1</mechanicalReduction>
		</actuator>
	</transmission>
	<link name="J4">
		<visual>
			<origin rpy="0 0 0" xyz="0 0 0"/>
			<geometry>
				<mesh filename="package://denso_robot_descriptions/ve026a_description/J4.dae" scale="1 1 1"/>
			</geometry>
		</visual>
		<collision>
			<origin rpy="0 0 0" xyz="0 0 0"/>
			<geometry>
				<mesh filename="package://denso_robot_descriptions/ve026a_description/J4.dae" scale="1 1 1"/>
			</geometry>
		</collision>
		<inertial>
			<mass value="1"/>
			<origin rpy="0.000000 0.000000 0.000000" xyz="0.000000 0.000000 0.000000"/>
			<inertia ixx="1" ixy="0" ixz="0" iyy="1" iyz="0" izz="1"/>
		</inertial>
	</link>
	<joint name="joint_4" type="revolute">
		<parent link="J3"/>
		<child link="J4"/>
		<origin rpy="0.000000 0.000000 0.000000" xyz="0.000000 0.000000 -0.230000"/>
		<axis xyz="-0.000000 -0.000000 1.000000"/>
		<limit effort="1" lower="-2.443461" upper="2.443461" velocity="1"/>
		<dynamics damping="0" friction="0"/>
	</joint>
	<transmission name="trans_4">
		<type>transmission_interface/SimpleTransmission</type>
		<joint name="joint_4">
			<hardwareInterface>PositionJointInterface</hardwareInterface>
		</joint>
		<actuator name="motor_4">
			<hardwareInterface>PositionJointInterface</hardwareInterface>
			<mechanicalReduction>1</mechanicalReduction>
		</actuator>
	</transmission>
	<link name="J5">
		<visual>
			<origin rpy="0 0 0" xyz="0 0 0"/>
			<geometry>
				<mesh filename="package://denso_robot_descriptions/ve026a_description/J5.dae" scale="1 1 1"/>
			</geometry>
		</visual>
		<collision>
			<origin rpy="0 0 0" xyz="0 0 0"/>
			<geometry>
				<mesh filename="package://denso_robot_descriptions/ve026a_description/J5.dae" scale="1 1 1"/>
			</geometry>
		</collision>
		<inertial>
			<mass value="1"/>
			<origin rpy="0.000000 0.000000 0.000000" xyz="0.000000 0.000000 0.000000"/>
			<inertia ixx="1" ixy="0" ixz="0" iyy="1" iyz="0" izz="1"/>
		</inertial>
	</link>
	<joint name="joint_5" type="revolute">
		<parent link="J4"/>
		<child link="J5"/>
		<origin rpy="0.000000 0.000000 0.000000" xyz="0.000000 0.000000 0.320000"/>
		<axis xyz="-0.000000 1.000000 -0.000000"/>
		<limit effort="1" lower="-1.570796" upper="1.832596" velocity="1"/>
		<dynamics damping="0" friction="0"/>
	</joint>
	<transmission name="trans_5">
		<type>transmission_interface/SimpleTransmission</type>
		<joint name="joint_5">
			<hardwareInterface>PositionJointInterface</hardwareInterface>
		</joint>
		<actuator name="motor_5">
			<hardwareInterface>PositionJointInterface</hardwareInterface>
			<mechanicalReduction>1</mechanicalReduction>
		</actuator>
	</transmission>
	<link name="J6">
		<visual>
			<origin rpy="0 0 0" xyz="0 0 0"/>
			<geometry>
				<mesh filename="package://denso_robot_descriptions/ve026a_description/J6.dae" scale="1 1 1"/>
			</geometry>
		</visual>
		<collision>
			<origin rpy="0 0 0" xyz="0 0 0"/>
			<geometry>
				<mesh filename="package://denso_robot_descriptions/ve026a_description/J6.dae" scale="1 1 1"/>
			</geometry>
		</collision>
		<inertial>
			<mass value="1"/>
			<origin rpy="0.000000 0.000000 0.000000" xyz="0.000000 0.000000 0.000000"/>
			<inertia ixx="1" ixy="0" ixz="0" iyy="1" iyz="0" izz="1"/>
		</inertial>
	</link>
	<joint name="joint_6" type="revolute">
		<parent link="J5"/>
		<child link="J6"/>
		<origin rpy="0.000000 0.000000 0.000000" xyz="0.000000 0.000000 -0.320000"/>
		<axis xyz="0.000000 0.000000 0.000000"/>
		<limit effort="1" lower="-2.443461" upper="2.443461" velocity="1"/>
		<dynamics damping="0" friction="0"/>
	</joint>
	<transmission name="trans_6">
		<type>transmission_interface/SimpleTransmission</type>
		<joint name="joint_6">
			<hardwareInterface>PositionJointInterface</hardwareInterface>
		</joint>
		<actuator name="motor_6">
			<hardwareInterface>PositionJointInterface</hardwareInterface>
			<mechanicalReduction>1</mechanicalReduction>
		</actuator>
	</transmission>
</robot>
